<?xml version="1.0" ?>
<sdf version="1.10">
  <world name="ROV_ENV_01">
    <physics name="1ms" type="dart">
      <max_step_size>0.001</max_step_size>
      <real_time_factor>0.2</real_time_factor>
    </physics>
    <gravity> 0 0 0</gravity>
    <plugin
      filename="gz-sim-physics-system"
      name="gz::sim::systems::Physics">
    </plugin>
    <plugin
      filename="gz-sim-scene-broadcaster-system"
      name="gz::sim::systems::SceneBroadcaster">
    </plugin>
    
    <plugin filename ="gz-sim-apply-link-wrench-system" 
            name="gz::sim::systems::ApplyLinkWrench"/>
            
    <scene>
      <!-- For turquoise ambient -->
      <ambient>0.0 1.0 1.0</ambient>
      <background>0.0 0.7 0.8</background>
    </scene>

    <light type="directional" name="sun">
      <cast_shadows>true</cast_shadows>
      <pose>0 0 10 0 0 0</pose>
      <diffuse>0.8 0.8 0.8 1</diffuse>
      <specular>0.2 0.2 0.2 1</specular>
      <attenuation>
        <range>1000</range>
        <constant>0.9</constant>
        <linear>0.01</linear>
        <quadratic>0.001</quadratic>
      </attenuation>
      <direction>0.5 0.1 -0.9</direction>
    </light>
        
    <model name="ground_plane">
      <pose relative_to="world">0 0 -1 0 0 0</pose>
      <static>true</static>
      <link name="link">
        <pose>0 0 0 0 0 0</pose>
        <collision name="collision">
          <pose relative_to="__model__">0 0 0 0 0 0</pose>
        <geometry>
          <plane>
          <normal>0 0 1</normal>
          </plane>
        </geometry>
        </collision>
        <visual name="visual">
        <pose relative_to="__model__">0 0 0 0 0 0</pose>
        <geometry>
          <plane>
          <normal>0 0 1</normal>
          <size>1000 1000</size>
          </plane>
        </geometry>
        <material>
          <ambient>0.8 0.8 0.8 1</ambient>
          <diffuse>0.8 0.8 0.8 1</diffuse>
          <specular>0.8 0.8 0.8 1</specular>
        </material>
        </visual>
      </link>
    </model>
           
    <model name="ROV" canonical_link="chassis">
      <plugin filename ="gz-sim-apply-link-wrench-system" 
            name="gz::sim::systems::ApplyLinkWrench"/>
      <plugin name="gz::sim::systems::OdometryPublisher"
                filename="gz-sim-odometry-publisher-system">
                <robot_base_frame>rov_charging_cylinder</robot_base_frame>
                <odom_topic>/rov/odometry</odom_topic>
                <dimensions>3</dimensions>
                <xyz_offset>1 0 -0.67 0 0 0</xyz_offset>
      </plugin>
      <pose relative_to="world">-1.25 0 0.78 0 0 0</pose> <!--Desired x -1, desired z + 0.67-->
      <link name="chassis">
        
        
        <pose relative_to="__model__">0 0 0 0 0 0</pose>
        <inertial>
          <mass>1400</mass>
          <inertia>
            <ixx>265.00</ixx>
            <!--ixx>100000</ixx-->
            <ixy>0</ixy>
            <ixz>0</ixz>
            <iyy>1919.04</iyy>
            <!--iyy>100000</iyy-->
            <iyz>0</iyz>
            <izz>2079.29</izz>
            <!--izz>100000</izz-->
          </inertia>

          <fluid_added_mass>
            <xx>700</xx>
            <yy>2268</yy>
            <zz>6258</zz>
          </fluid_added_mass>
        </inertial>
        <visual name="visual">
          <geometry>
            <box>
              <size>4 1.35 0.67</size>
            </box>
          </geometry>
          
          <material>
          
            <ambient>1.0 0.5 0.2 1.0</ambient>
            <diffuse>1.0 0.5 0.2 1.0</diffuse>
            <specular>0.5 0.3 0.1 1.0</specular>
            
          </material>
        </visual>
          <collision name="collision">
            <geometry>
              <box>
                <size>4 1.35 0.67</size>
              </box>
            </geometry>
          </collision>
      </link>
      
      <link name="rov_charging_cylinder">
          <pose relative_to="__model__">1 0 -0.335 0 0 0</pose>
        
          <!--pose relative_to="__link__">0 0 0 0 0 0</pose-->
          <!--ODOMETRY PUBLISHER, sending to magnetic data node-->
          
        <collision name="collision">  
          <geometry>
            <cylinder>
              <radius>0.155</radius>
              <length>0.67</length>
            </cylinder>
          </geometry>
        </collision>
        <visual name="visual">
        <!--pose>0 0 0 0 0 0</pose-->
        <geometry>
          <cylinder>
            <radius>0.155</radius>
            <length>0.67</length>
          </cylinder>
        </geometry>
        <material>
            <ambient>0 0 0.5 1</ambient>       
            <diffuse>0 0 0.5 1</diffuse>       
            <specular>0.2 0.2 0.5 1</specular> 
            <emissive>0 0 0.2 1</emissive>
        </material>
        </visual>
        </link>
        <joint name="rov_charging_cylinder_joint" type="fixed">
         <pose relative_to="chassis"/>
              <parent>chassis</parent>
              <child>rov_charging_cylinder</child>
      </joint> 



     <plugin filename="gz-sim-hydrodynamics-system"
            name="gz::sim::systems::Hydrodynamics">
            <link_name>chassis</link_name>
            <water_density>1000.0</water_density>
            <!--xDotU>700</xDotU--> <!--Added mass in surge-->
            <!--yDotV>1000</yDotV--> <!--Added mass in sway-->
            <!--zDotW>1000</zDotW--> <!--Added mass in heave-->
            <!--kDotP>100</kDotP--> <!--Added mass in roll-->
            <!--mDotQ>100</mDotQ--> <!--Added mass in pitch-->
            <!--nDotR>100</nDotR--> <!--Added mass in yaw-->
            <xUabsU>-1</xUabsU> <!--Quadratic drag in surge-->
            <xU>-20</xU> <!--Linear drag in surge-->
            <yVabsV>-1</yVabsV> <!--Quadratic drag in sway-->
            <yV>-2500</yV> <!--Linear drag in sway-->
            <zWabsW>-1</zWabsW> <!--Quadratic drag in heave-->
            <zW>-3000</zW> <!--Linear drag in heave-->
            <kPabsP>-1</kPabsP> <!--Quadratic drag in roll-->
            <kP>-400</kP> <!--Linear drag in roll-->
            <mQabsQ>-1</mQabsQ> <!--Quadratic drag in pitch-->
            <mQ>-600</mQ> <!--Linear drag in pitch-->
            <nRabsR>-1</nRabsR> <!--Quadratic drag in yaw-->
            <nR>-1500</nR> <!--Linear drag in yaw-->
            <default_current>0 0 0</default_current>
      </plugin>
        


        <link name="stern_thruster_cylinder">
            <pose relative_to="chassis">-2 0 0 0 1.5707 0</pose>
            
            <!--inertial>
              <mass>10</mass>
              <inertia>
                <ixx>0.0583</ixx>
                <ixy>0</ixy>
                <ixz>0</ixz>
                <iyy>0.0583</iyy>
                <iyz>0</iyz>
                <izz>0.050</izz>
              </inertia>
            </inertial-->
            
            <visual name="visual">

              <geometry>
                <cylinder>
                  <radius>0.025</radius>
                  <length>0.2</length>
                </cylinder>
              </geometry>
            </visual>

            <collision name="collision">

              <geometry>
                <cylinder>
                  <radius>0.025</radius>
                  <length>0.2</length>
                </cylinder>
              </geometry>
            </collision>
            </link>
          
            <joint name="stern_thruster_cylinder_joint" type="revolute">
              <pose relative_to="stern_thruster_cylinder"/>
              <parent>chassis</parent>
              <child>stern_thruster_cylinder</child>
              <axis>
                <xyz expressed_in="__model__">1 0 0</xyz>
                <limit>
                  <lower>-1.79769e+308</lower>
                  <upper>1.79769e+308</upper>
                </limit>
              </axis>
            </joint> 

            <joint name="stern_thruster_cylinder_blade1_joint" type="fixed">
              <pose relative_to="stern_thruster_blade_1"/>
              <parent>stern_thruster_cylinder</parent>
              <child>stern_thruster_blade_1</child>
            </joint>

            <joint name="stern_thruster_cylinder_blade2_joint" type="fixed">
              <pose relative_to="stern_thruster_blade_2"/>
              <parent>stern_thruster_cylinder</parent>
              <child>stern_thruster_blade_2</child>
            </joint>


          <link name="stern_thruster_blade_1">
            <pose relative_to="stern_thruster_cylinder">0 -0.08 -0.06 0 0.7 0</pose>
              <!--inertial>
                 <mass>1</mass>
                <inertia>
                  <ixx>0.1</ixx>
                  <ixy>0</ixy>
                  <ixz>0</ixz>
                  <iyy>0.1</iyy>
                  <iyz>0</iyz>
                  <izz>0.1</izz>
                </inertia>
              </inertial-->
            
            <visual name="visual">

              <geometry>
                <box>
                  <size>0.01 0.15 0.05</size>
                </box>
              </geometry>
            </visual>

            <collision name="collision">
              <geometry>
                <box>
                  <size>0.01 0.15 0.05</size>
                </box>
              </geometry>
            </collision>
            
          </link>
          
          <link name="stern_thruster_blade_2">
            <pose relative_to="stern_thruster_cylinder">0 0.08 -0.06 0 -0.7 0</pose>
              <!--inertial>
                 <mass>1</mass>
                <inertia>
                  <ixx>0.1</ixx>
                  <ixy>0</ixy>
                  <ixz>0</ixz>
                  <iyy>0.1</iyy>
                  <iyz>0</iyz>
                  <izz>0.1</izz>
                </inertia>
              </inertial-->
            
            <visual name="visual">

              <geometry>
                <box>
                  <size>0.02 0.15 0.05</size>
                </box>
              </geometry>
            </visual>

            <collision name="collision">
              <geometry>
                <box>
                  <size>0.02 0.15 0.05</size>
                </box>
              </geometry>
            </collision>
            
          </link>
          <plugin name="gz::sim::systems::Thruster"
                    filename="gz-sim-thruster-system">
                    <namespace>rov_cmd</namespace>
                    <topic>stern_thrust</topic>
                    <joint_name>stern_thruster_cylinder_joint</joint_name>
                    <use_angvel_cmd>0</use_angvel_cmd>
                    <fluid_density>1000</fluid_density>
                    <propeller_diameter>0.10</propeller_diameter>
                    <thrust_coefficient>0.8</thrust_coefficient>
                    <velocity_control>0</velocity_control> <!--if true, use joint velocity commands to rotate the propeller. If false, use a PID controller to apply wrenches directly to the propeller link instead. [Optional, defaults to false].-->
                    <p_gain>0.5</p_gain>
                    <i_gain>0</i_gain>
                    <d_gain>0</d_gain>
                    <max_thrust_cmd>1000</max_thrust_cmd>
                    <min_thrust_cmd>-1000</min_thrust_cmd>
                    <deadband>0</deadband>
                    <wake_fraction>0.2</wake_fraction>
                    <alpha_1>1</alpha_1>
                    <alpha_2>0</alpha_2>
        </plugin>

        <link name="starboard_thruster_cylinder">
            <pose relative_to="chassis">0 -0.675 0 -1.5707 0 0</pose>
            
            <!--inertial>
              <mass>10</mass>
              <inertia>
                <ixx>0.0583</ixx>
                <ixy>0</ixy>
                <ixz>0</ixz>
                <iyy>0.0583</iyy>
                <iyz>0</iyz>
                <izz>0.050</izz>
              </inertia>
            </inertial-->
            
            <visual name="visual">

              <geometry>
                <cylinder>
                  <radius>0.025</radius>
                  <length>0.2</length>
                </cylinder>
              </geometry>
            </visual>

            <collision name="collision">

              <geometry>
                <cylinder>
                  <radius>0.025</radius>
                  <length>0.2</length>
                </cylinder>
              </geometry>
            </collision>
            </link>
          
            <joint name="starboard_thruster_cylinder_joint" type="revolute">
              <pose relative_to="starboard_thruster_cylinder"/>
              <parent>chassis</parent>
              <child>starboard_thruster_cylinder</child>
              <axis>
                <xyz expressed_in="__model__">0 1 0</xyz>
                <limit>
                  <lower>-1.79769e+308</lower>
                  <upper>1.79769e+308</upper>
                </limit>
              </axis>
            </joint> 

            <joint name="starboard_thruster_cylinder_blade1_joint" type="fixed">
              <pose relative_to="starboard_thruster_blade_1"/>
              <parent>starboard_thruster_cylinder</parent>
              <child>starboard_thruster_blade_1</child>
            </joint>

            <joint name="starboard_thruster_cylinder_blade2_joint" type="fixed">
              <pose relative_to="starboard_thruster_blade_2"/>
              <parent>starboard_thruster_cylinder</parent>
              <child>starboard_thruster_blade_2</child>
            </joint>


          <link name="starboard_thruster_blade_1">
            <pose relative_to="starboard_thruster_cylinder">0 -0.08 -0.06 0 0.7 0</pose>
              <!--inertial>
                 <mass>1</mass>
                <inertia>
                  <ixx>0.1</ixx>
                  <ixy>0</ixy>
                  <ixz>0</ixz>
                  <iyy>0.1</iyy>
                  <iyz>0</iyz>
                  <izz>0.1</izz>
                </inertia>
              </inertial-->
            
            <visual name="visual">

              <geometry>
                <box>
                  <size>0.01 0.15 0.05</size>
                </box>
              </geometry>
            </visual>

            <collision name="collision">
              <geometry>
                <box>
                  <size>0.01 0.15 0.05</size>
                </box>
              </geometry>
            </collision>
            
          </link>
          
          <link name="starboard_thruster_blade_2">
            <pose relative_to="starboard_thruster_cylinder">0 0.08 -0.06 0 -0.7 0</pose>
              <!--inertial>
                <mass>1</mass>
                <inertia>
                  <ixx>0.1</ixx>
                  <ixy>0</ixy>
                  <ixz>0</ixz>
                  <iyy>0.1</iyy>
                  <iyz>0</iyz>
                  <izz>0.1</izz>
                </inertia>
              </inertial-->
            
            <visual name="visual">

              <geometry>
                <box>
                  <size>0.02 0.15 0.05</size>
                </box>
              </geometry>
            </visual>

            <collision name="collision">
              <geometry>
                <box>
                  <size>0.02 0.15 0.05</size>
                </box>
              </geometry>
            </collision>
            
          </link>
          <plugin name="gz::sim::systems::Thruster"
                    filename="gz-sim-thruster-system">
                    <namespace>rov_cmd</namespace>
                    <topic>starboard_thrust</topic>
                    <joint_name>starboard_thruster_cylinder_joint</joint_name>
                    <use_angvel_cmd>0</use_angvel_cmd>
                    <fluid_density>1000</fluid_density>
                    <propeller_diameter>0.10</propeller_diameter>
                    <thrust_coefficient>0.8</thrust_coefficient>
                    <velocity_control>0</velocity_control> <!--if true, use joint velocity commands to rotate the propeller. If false, use a PID controller to apply wrenches directly to the propeller link instead. [Optional, defaults to false].-->
                    <p_gain>0.5</p_gain>
                    <i_gain>0</i_gain>
                    <d_gain>0</d_gain>
                    <max_thrust_cmd>1000</max_thrust_cmd>
                    <min_thrust_cmd>-1000</min_thrust_cmd>
                    <deadband>0</deadband>
                    <wake_fraction>0.2</wake_fraction>
                    <alpha_1>1</alpha_1>
                    <alpha_2>0</alpha_2>
        </plugin>

        <link name="port_thruster_cylinder">
            <pose relative_to="chassis">0 0.675 0 1.5707 0 0</pose>
            
            <!--inertial>
              <mass>10</mass>
              <inertia>
                <ixx>0.0583</ixx>
                <ixy>0</ixy>
                <ixz>0</ixz>
                <iyy>0.0583</iyy>
                <iyz>0</iyz>
                <izz>0.050</izz>
              </inertia>
            </inertial-->
            
            <visual name="visual">

              <geometry>
                <cylinder>
                  <radius>0.025</radius>
                  <length>0.2</length>
                </cylinder>
              </geometry>
            </visual>

            <collision name="collision">

              <geometry>
                <cylinder>
                  <radius>0.025</radius>
                  <length>0.2</length>
                </cylinder>
              </geometry>
            </collision>
            </link>
          
            <joint name="port_thruster_cylinder_joint" type="revolute">
              <pose relative_to="port_thruster_cylinder"/>
              <parent>chassis</parent>
              <child>port_thruster_cylinder</child>
              <axis>
                <xyz expressed_in="__model__">0 -1 0</xyz>
                <limit>
                  <lower>-1.79769e+308</lower>
                  <upper>1.79769e+308</upper>
                </limit>
              </axis>
            </joint> 

            <joint name="port_thruster_cylinder_blade1_joint" type="fixed">
              <pose relative_to="port_thruster_blade_1"/>
              <parent>port_thruster_cylinder</parent>
              <child>port_thruster_blade_1</child>
            </joint>

            <joint name="port_thruster_cylinder_blade2_joint" type="fixed">
              <pose relative_to="port_thruster_blade_2"/>
              <parent>port_thruster_cylinder</parent>
              <child>port_thruster_blade_2</child>
            </joint>


          <link name="port_thruster_blade_1">
            <pose relative_to="port_thruster_cylinder">0 -0.08 -0.06 0 0.7 0</pose>
            <!--inertial>
               <mass>1</mass>
                <inertia>
                  <ixx>0.1</ixx>
                  <ixy>0</ixy>
                  <ixz>0</ixz>
                  <iyy>0.1</iyy>
                  <iyz>0</iyz>
                  <izz>0.1</izz>
                </inertia>
              </inertial-->
            
            <visual name="visual">

              <geometry>
                <box>
                  <size>0.01 0.15 0.05</size>
                </box>
              </geometry>
            </visual>

            <collision name="collision">
              <geometry>
                <box>
                  <size>0.01 0.15 0.05</size>
                </box>
              </geometry>
            </collision>
            
          </link>
          
          <link name="port_thruster_blade_2">
            <pose relative_to="port_thruster_cylinder">0 0.08 -0.06 0 -0.7 0</pose>
              <!--inertial>
                 <mass>1</mass>
                <inertia>
                  <ixx>0.1</ixx>
                  <ixy>0</ixy>
                  <ixz>0</ixz>
                  <iyy>0.1</iyy>
                  <iyz>0</iyz>
                  <izz>0.1</izz>
                </inertia>
              </inertial-->
            
            <visual name="visual">

              <geometry>
                <box>
                  <size>0.02 0.15 0.05</size>
                </box>
              </geometry>
            </visual>

            <collision name="collision">
              <geometry>
                <box>
                  <size>0.02 0.15 0.05</size>
                </box>
              </geometry>
            </collision>
            
          </link>
          <plugin name="gz::sim::systems::Thruster"
                    filename="gz-sim-thruster-system">
                    <namespace>rov_cmd</namespace>
                    <topic>port_thrust</topic>
                    <joint_name>port_thruster_cylinder_joint</joint_name>
                    <use_angvel_cmd>0</use_angvel_cmd>
                    <fluid_density>1000</fluid_density>
                    <propeller_diameter>0.10</propeller_diameter>
                    <thrust_coefficient>0.8</thrust_coefficient>
                    <velocity_control>0</velocity_control> <!--if true, use joint velocity commands to rotate the propeller. If false, use a PID controller to apply wrenches directly to the propeller link instead. [Optional, defaults to false].-->
                    <p_gain>0.5</p_gain>
                    <i_gain>0</i_gain>
                    <d_gain>0</d_gain>
                    <max_thrust_cmd>1000</max_thrust_cmd>
                    <min_thrust_cmd>-1000</min_thrust_cmd>
                    <deadband>0</deadband>
                    <wake_fraction>0.2</wake_fraction>
                    <alpha_1>1</alpha_1>
                    <alpha_2>0</alpha_2>
        </plugin>

        <link name="bow_thruster_cylinder">
            <pose relative_to="chassis">2 0 0 0 -1.5707 0</pose>
            
            <!--inertial>
              <mass>10</mass>
              <inertia>
                <ixx>0.0583</ixx>
                <ixy>0</ixy>
                <ixz>0</ixz>
                <iyy>0.0583</iyy>
                <iyz>0</iyz>
                <izz>0.050</izz>
              </inertia>
            </inertial-->
            
            <visual name="visual">

              <geometry>
                <cylinder>
                  <radius>0.025</radius>
                  <length>0.2</length>
                </cylinder>
              </geometry>
            </visual>

            <collision name="collision">

              <geometry>
                <cylinder>
                  <radius>0.025</radius>
                  <length>0.2</length>
                </cylinder>
              </geometry>
            </collision>
            </link>
          
            <joint name="bow_thruster_cylinder_joint" type="revolute">
              <pose relative_to="bow_thruster_cylinder"/>
              <parent>chassis</parent>
              <child>bow_thruster_cylinder</child>
              <axis>
                <xyz expressed_in="__model__">-1 0 0</xyz>
                <limit>
                  <lower>-1.79769e+308</lower>
                  <upper>1.79769e+308</upper>
                </limit>
              </axis>
            </joint> 

            <joint name="bow_thruster_cylinder_blade1_joint" type="fixed">
              <pose relative_to="bow_thruster_blade_1"/>
              <parent>bow_thruster_cylinder</parent>
              <child>bow_thruster_blade_1</child>
            </joint>

            <joint name="bow_thruster_cylinder_blade2_joint" type="fixed">
              <pose relative_to="bow_thruster_blade_2"/>
              <parent>bow_thruster_cylinder</parent>
              <child>bow_thruster_blade_2</child>
            </joint>


          <link name="bow_thruster_blade_1">
            <pose relative_to="bow_thruster_cylinder">0 -0.08 -0.06 0 0.7 0</pose>
              <!--inertial>
               <mass>1</mass>
                <inertia>
                  <ixx>0.1</ixx>
                  <ixy>0</ixy>
                  <ixz>0</ixz>
                  <iyy>0.1</iyy>
                  <iyz>0</iyz>
                  <izz>0.1</izz>
                </inertia>
              </inertial-->
            
            <visual name="visual">

              <geometry>
                <box>
                  <size>0.01 0.15 0.05</size>
                </box>
              </geometry>
            </visual>

            <collision name="collision">
              <geometry>
                <box>
                  <size>0.01 0.15 0.05</size>
                </box>
              </geometry>
            </collision>
            
          </link>
          
          <link name="bow_thruster_blade_2">
            <pose relative_to="bow_thruster_cylinder">0 0.08 -0.06 0 -0.7 0</pose>
              <!--inertial>
                <mass>1</mass>
                <inertia>
                  <ixx>0.1</ixx>
                  <ixy>0</ixy>
                  <ixz>0</ixz>
                  <iyy>0.1</iyy>
                  <iyz>0</iyz>
                  <izz>0.1</izz>
                </inertia>
              </inertial-->
            
            <visual name="visual">

              <geometry>
                <box>
                  <size>0.02 0.15 0.05</size>
                </box>
              </geometry>
            </visual>

            <collision name="collision">
              <geometry>
                <box>
                  <size>0.02 0.15 0.05</size>
                </box>
              </geometry>
            </collision>
            
          </link>
          <plugin name="gz::sim::systems::Thruster"
                    filename="gz-sim-thruster-system">
                    <namespace>rov_cmd</namespace>
                    <topic>bow_thrust</topic>
                    <joint_name>bow_thruster_cylinder_joint</joint_name>
                    <use_angvel_cmd>0</use_angvel_cmd>
                    <fluid_density>1000</fluid_density>
                    <propeller_diameter>0.10</propeller_diameter>
                    <thrust_coefficient>0.8</thrust_coefficient>
                    <velocity_control>0</velocity_control> <!--if true, use joint velocity commands to rotate the propeller. If false, use a PID controller to apply wrenches directly to the propeller link instead. [Optional, defaults to false].-->
                    <p_gain>0.5</p_gain>
                    <i_gain>0</i_gain>
                    <d_gain>0</d_gain>
                    <max_thrust_cmd>1000</max_thrust_cmd>
                    <min_thrust_cmd>-1000</min_thrust_cmd>
                    <deadband>0</deadband>
                    <wake_fraction>0.2</wake_fraction>
                    <alpha_1>1</alpha_1>
                    <alpha_2>0</alpha_2>
        </plugin>

        <link name="top_thruster_cylinder">
            <pose relative_to="chassis">0 0 0.335 3.141592 0 0</pose>
            
            <!--inertial>
              <mass>10</mass>
              <inertia>
                <ixx>0.0583</ixx>
                <ixy>0</ixy>
                <ixz>0</ixz>
                <iyy>0.0583</iyy>
                <iyz>0</iyz>
                <izz>0.050</izz>
              </inertia>
            </inertial-->
            
            <visual name="visual">

              <geometry>
                <cylinder>
                  <radius>0.025</radius>
                  <length>0.2</length>
                </cylinder>
              </geometry>
            </visual>

            <collision name="collision">

              <geometry>
                <cylinder>
                  <radius>0.025</radius>
                  <length>0.2</length>
                </cylinder>
              </geometry>
            </collision>
            </link>
          
            <joint name="top_thruster_cylinder_joint" type="revolute">
              <pose relative_to="top_thruster_cylinder"/>
              <parent>chassis</parent>
              <child>top_thruster_cylinder</child>
              <axis>
                <xyz expressed_in="__model__">0 0 -1</xyz>
                <limit>
                  <lower>-1.79769e+308</lower>
                  <upper>1.79769e+308</upper>
                </limit>
              </axis>
            </joint> 

            <joint name="top_thruster_cylinder_blade1_joint" type="fixed">
              <pose relative_to="top_thruster_blade_1"/>
              <parent>top_thruster_cylinder</parent>
              <child>top_thruster_blade_1</child>
            </joint>

            <joint name="top_thruster_cylinder_blade2_joint" type="fixed">
              <pose relative_to="top_thruster_blade_2"/>
              <parent>top_thruster_cylinder</parent>
              <child>top_thruster_blade_2</child>
            </joint>


          <link name="top_thruster_blade_1">
            <pose relative_to="top_thruster_cylinder">0 -0.08 -0.06 0 0.7 0</pose>
              <!--inertial>
               <mass>1</mass>
                <inertia>
                  <ixx>0.1</ixx>
                  <ixy>0</ixy>
                  <ixz>0</ixz>
                  <iyy>0.1</iyy>
                  <iyz>0</iyz>
                  <izz>0.1</izz>
                </inertia>
              </inertial-->
            
            <visual name="visual">

              <geometry>
                <box>
                  <size>0.01 0.15 0.05</size>
                </box>
              </geometry>
            </visual>

            <collision name="collision">
              <geometry>
                <box>
                  <size>0.01 0.15 0.05</size>
                </box>
              </geometry>
            </collision>
            
          </link>
          
          <link name="top_thruster_blade_2">
            <pose relative_to="top_thruster_cylinder">0 0.08 -0.06 0 -0.7 0</pose>
              <!--inertial>
                 <mass>1</mass>
                <inertia>
                  <ixx>0.1</ixx>
                  <ixy>0</ixy>
                  <ixz>0</ixz>
                  <iyy>0.1</iyy>
                  <iyz>0</iyz>
                  <izz>0.1</izz>
                </inertia>
              </inertial-->
            
            <visual name="visual">

              <geometry>
                <box>
                  <size>0.02 0.15 0.05</size>
                </box>
              </geometry>
            </visual>

            <collision name="collision">
              <geometry>
                <box>
                  <size>0.02 0.15 0.05</size>
                </box>
              </geometry>
            </collision>
            
          </link>
          <plugin name="gz::sim::systems::Thruster"
                    filename="gz-sim-thruster-system">
                    <namespace>rov_cmd</namespace>
                    <topic>top_thrust</topic>
                    <joint_name>top_thruster_cylinder_joint</joint_name>
                    <use_angvel_cmd>0</use_angvel_cmd>
                    <fluid_density>1000</fluid_density>
                    <propeller_diameter>0.10</propeller_diameter>
                    <thrust_coefficient>0.8</thrust_coefficient>
                    <velocity_control>0</velocity_control> <!--if true, use joint velocity commands to rotate the propeller. If false, use a PID controller to apply wrenches directly to the propeller link instead. [Optional, defaults to false].-->
                    <p_gain>0.5</p_gain>
                    <i_gain>0</i_gain>
                    <d_gain>0</d_gain>
                    <max_thrust_cmd>1000</max_thrust_cmd>
                    <min_thrust_cmd>-1000</min_thrust_cmd>
                    <deadband>0</deadband>
                    <wake_fraction>0.2</wake_fraction>
                    <alpha_1>1</alpha_1>
                    <alpha_2>0</alpha_2>
        </plugin>

        <link name="bottom_thruster_cylinder">
            <pose relative_to="chassis">0 0 -0.335 0 0 0</pose>
            
            <!--inertial>
              <mass>10</mass>
              <inertia>
                <ixx>0.0583</ixx>
                <ixy>0</ixy>
                <ixz>0</ixz>
                <iyy>0.0583</iyy>
                <iyz>0</iyz>
                <izz>0.050</izz>
              </inertia>
            </inertial-->
            
            <visual name="visual">

              <geometry>
                <cylinder>
                  <radius>0.025</radius>
                  <length>0.2</length>
                </cylinder>
              </geometry>
            </visual>

            <collision name="collision">

              <geometry>
                <cylinder>
                  <radius>0.025</radius>
                  <length>0.2</length>
                </cylinder>
              </geometry>
            </collision>
            </link>
          
            <joint name="bottom_thruster_cylinder_joint" type="revolute">
              <pose relative_to="bottom_thruster_cylinder"/>
              <parent>chassis</parent>
              <child>bottom_thruster_cylinder</child>
              <axis>
                <xyz expressed_in="__model__">0 0 1</xyz>
                <limit>
                  <lower>-1.79769e+308</lower>
                  <upper>1.79769e+308</upper>
                </limit>
              </axis>
            </joint> 

            <joint name="bottom_thruster_cylinder_blade1_joint" type="fixed">
              <pose relative_to="bottom_thruster_blade_1"/>
              <parent>bottom_thruster_cylinder</parent>
              <child>bottom_thruster_blade_1</child>
            </joint>

            <joint name="bottom_thruster_cylinder_blade2_joint" type="fixed">
              <pose relative_to="bottom_thruster_blade_2"/>
              <parent>bottom_thruster_cylinder</parent>
              <child>bottom_thruster_blade_2</child>
            </joint>


          <link name="bottom_thruster_blade_1">
            <pose relative_to="bottom_thruster_cylinder">0 -0.08 -0.06 0 0.7 0</pose>
              <!--inertial>
                <mass>1</mass>
                <inertia>
                  <ixx>0.1</ixx>
                  <ixy>0</ixy>
                  <ixz>0</ixz>
                  <iyy>0.1</iyy>
                  <iyz>0</iyz>
                  <izz>0.1</izz>
                </inertia>
              </inertial-->
            
            <visual name="visual">

              <geometry>
                <box>
                  <size>0.01 0.15 0.05</size>
                </box>
              </geometry>
            </visual>

            <collision name="collision">
              <geometry>
                <box>
                  <size>0.01 0.15 0.05</size>
                </box>
              </geometry>
            </collision>
            
          </link>
          
          <link name="bottom_thruster_blade_2">
            <pose relative_to="bottom_thruster_cylinder">0 0.08 -0.06 0 -0.7 0</pose>
              <!--inertial>
                <mass>1</mass>
                <inertia>
                  <ixx>0.1</ixx>
                  <ixy>0</ixy>
                  <ixz>0</ixz>
                  <iyy>0.1</iyy>
                  <iyz>0</iyz>
                  <izz>0.1</izz>
                </inertia>
              </inertial-->
            
            <visual name="visual">

              <geometry>
                <box>
                  <size>0.02 0.15 0.05</size>
                </box>
              </geometry>
            </visual>

            <collision name="collision">
              <geometry>
                <box>
                  <size>0.02 0.15 0.05</size>
                </box>
              </geometry>
            </collision>
            
          </link>
          <plugin name="gz::sim::systems::Thruster"
                    filename="gz-sim-thruster-system">
                    <namespace>rov_cmd</namespace>
                    <topic>bottom_thrust</topic>
                    <joint_name>bottom_thruster_cylinder_joint</joint_name>
                    <use_angvel_cmd>0</use_angvel_cmd>
                    <fluid_density>1000</fluid_density>
                    <propeller_diameter>0.10</propeller_diameter>
                    <thrust_coefficient>0.8</thrust_coefficient>
                    <velocity_control>0</velocity_control> <!--if true, use joint velocity commands to rotate the propeller. If false, use a PID controller to apply wrenches directly to the propeller link instead. [Optional, defaults to false].-->
                    <p_gain>0.5</p_gain>
                    <i_gain>0</i_gain>
                    <d_gain>0</d_gain>
                    <max_thrust_cmd>1000</max_thrust_cmd>
                    <min_thrust_cmd>-1000</min_thrust_cmd>
                    <deadband>0</deadband>
                    <wake_fraction>0.2</wake_fraction>
                    <alpha_1>1</alpha_1>
                    <alpha_2>0</alpha_2>
        </plugin>



       
        


    </model>
  
  <model name="docking_cylinder"
          canonical_link="cylinder_link">
        <pose relative_to="world">0 0 -1 0 0 0</pose>
        <static>true</static>
        <link name="cylinder_link">
        <pose relative_to="__model__">0 0 0 0 0 0</pose>
        <collision name="collision">
          <pose relative_to="__model__">0 0 0 0 0 0</pose>
          <geometry>
            <cylinder>
              <radius>0.18</radius>
              <length>2</length>
            </cylinder>
          </geometry>
        </collision>
        <visual name="visual">
        <pose relative_to="__model__">0 0 0 0 0 0</pose>
        <geometry>
          <cylinder>
            <radius>0.18</radius>
            <length>2</length>
          </cylinder>
        </geometry>
        <material>
            <ambient>1 0 0 1</ambient>      
            <diffuse>1 0 0 1</diffuse>     
            <specular>0.5 0.5 0.5 1</specular> 
            <emissive>0.2 0 0 1</emissive>   
        </material>
        </visual>
      </link>
  </model>

  <model name="docking_plate"
    canonical_link="docking_plate_link">
    <pose relative_to="world">0 0 -1 0 0 0</pose>
    <static>true</static>
    <link name="docking_plate_link">
      <pose relative_to="__model__">0 0 0 0 0 0</pose>
      <visual name="visual">
        <pose relative_to="__model__">0 0 0 0 0 0</pose>
        <geometry>
          <box>
            <size>6 2 1.8</size>
          </box>
        </geometry>
        <material>
          <ambient>1.0 0.5 0.2 1.0</ambient>
          <diffuse>1.0 0.5 0.2 1.0</diffuse>
          <specular>0.5 0.3 0.1 1.0</specular>
        </material>
      </visual>
    </link>
  </model>

    
  </world>
</sdf>
      
